<mujoco model="example">
  <compiler coordinate="global" autolimits="true"/>

  <default>
    <geom rgba=".8 .6 .4 1"/>
  </default>

  <asset>
    <texture type="skybox" builtin="gradient" rgb1="1 1 1" rgb2=".6 .8 1" width="256" height="256"/>
  </asset>

  <worldbody>
    <light pos="0 1 1" dir="0 -1 -1" diffuse="1 1 1"/>

    <body name='upper_arm'>
      <geom type="capsule" fromto="0 0 1.0  0 0 0.6" size="0.06"/>
      <joint name="shoulder" type="ball" pos="0 0 1"/>

      <body name='lower_arm'>
        <geom type="capsule" fromto="0 0 0.6  0.3 0 0.6" size="0.04" friction="1.0 0.5 0.1"/>
        <joint name='elbow' type="hinge" pos="0 0 0.6" axis="0 1 0"/>
        <site name="end1" pos="0.3 0 0.6" type="sphere" size="0.01"/>

      </body>

    </body>

    <body name='ball'>
      <geom type="sphere" pos="0.9 0 0.6" size="0.05"/>
      <site name="end2" pos="0.9 0 0.6" type="sphere" size="0.01"/>
      <joint type="free"/>
    </body>

  </worldbody>

  <tendon>
    <spatial limited="true" range="0 0.6" width="0.005">
      <site site="end1"/>
      <site site="end2"/>
    </spatial>
  </tendon>

  <actuator>
    <motor name="shoulder_motor" joint="shoulder" ctrlrange="-1 1" gear="50"/>
    <motor name="elbow_motor" joint="elbow" ctrlrange="-1 1" gear="50"/>
  </actuator>

</mujoco>